Workbook

Sheet H0系统预排
O1: SIT权限检查（ 外部：1代表权限已配好，反之则为2。 内部：3代表、权限已配好，反之则为4） | U1: 查看当前账号关联的经销商（单个）数据 | AI1: 查看当前登录事业部的所有数据 | AT1: 以事业部维度，查看个人创建或者个人关联经销商数据。特殊，列表看个人创建，单据详情可选全部经销商：折扣政策、战略报备），当菜单包含战略项目字样时，再增加一个或者当前单据的项目经理=当前用户 | AX1: 以事业部维度，查看个人创建或个人关联经销商或当前部门下属所管辖经销商数据 | AZ1: 查看当前登录事业部所有的数据 | CK1: MBO业务
A2: 菜单编码（唯一） | B2: 一级菜单 | C2: 二级菜单 | D2: 三级菜单 | E2: 菜单渠道属性 | F2: 经销商可阅 | G2: 内部可阅/废弃 | H2: 涉及系统 | I2: 生产需复核 | J2: AE_MENUID | K2: 备注 | L2: 原菜单路径1 | M2: 原菜单路径2 | N2: 原菜单路径3 | O2: 配置优先级 | P2: 技术配置 | Q2: 汉得复核 | R2: 箭牌复核sit | S2: 默认菜单按钮权限（针对本表所有角色） | T2: █经销商按钮权限█ | U2: 经销商 主账号 | V2: 法人账号 | W2: 经销商 负责人 | X2: 经销商 采购 | Y2: 经销商 仓管 | Z2: 经销商 财务 | AA2: 经销商工程报备 | AB2: 经销商家装报备 | AC2: 经销商产品专员 | AD2: 出口经销商 | AE2: 电子合同签章 | AF2: 经销商工程核销 | AG2: 经销商家装核销 | AH2: 经销商延期核销 | AI2: 价格查询 | AJ2: 工厂库存查询 | AL2: 库存查询 | AM2: 工程报备专员 | AN2: 家装报备专员 | AO2: 报备查询 | AP2: 工程合同专员 | AQ2: 家装合同专员 | AR2: 运营管理 | AS2: █报备、合同、运营默认按钮权限█ | AT2: 战略工程项目管理 | AU2: 工程项目管理 | AV2: 家装项目管理 | AW2: 区域销售代表 | AX2: 大区管理 | AY2: █项目、区域销售默认权限█ | AZ2: 发货专员 | BA2: 调度专员 | BB2: 计划物流 | BC2: █发货、调度、物流默认权限█ | BD2: 销售财务 | BE2: █销售财务默认权限█ | BF2: 认领核销 | BG2: BI人员查看 | BH2: AE-工程合同及折扣单查看 | BI2: 自营工程签收 | BJ2: 发票作废与取消核销 | BK2: 真实性核销审核 | BL2: 库存查询 | BM2: 库存查询（映射） | BN2: 价格查询 | BO2: 价格查询（导出） | BP2: 产品查询（所有） | BQ2: 产品查询（导出） | BR2: 产品查询 | BS2: 产品维护 | BT2: 产品推广等级维护 | BU2: 产品SM状态变更 | BV2: 售后产品SM状态变更 | BW2: 产品说明书维护 | BX2: 软装经理 | BY2: 软装总监 | BZ2: 合同及订单查询 | CA2: 展示总监（新增） | CB2: 合同档案管理员（新增） | CC2: 展示部人员 | CD2: 样品折扣政策查询 | CE2: 装修报销标准维护 | CF2: 门店档案资料查询（新） | CG2: 单体项目报备导出 | CH2: 家装折扣政策查询 | CI2: 门店装修报表查询 | CJ2: █产品维护权限█ | CK2: 培训师 | CL2: 活动策划师 | CM2: 设计师 | CN2: 培训管理员 | CO2: 活动策划管理员 | CP2: 设计师管理员 | CQ2: 集团合同管理员 | CR2: 问题反馈处理回复 | CS2: 菜单使用频率 | CT2: 最新更新时间（按sj精确到时分秒） | CU2: 更新记录（调整人+调整内容+调整时间）
A3: 1 | B3: 基础资料 | C3: 客户资料 | D3: 经销商档案 | E3: 全渠道 | F3: 是 | G3: 是 | H3: CRM/AE/MBO | J3: 12036281，12036115 | K3: （查询+新建地址） | O3: 3 | P3: 1、3 | T3: 编辑 | U3: √ | W3: √ | X3: √ | Z3: √ | AR3: √ | AW3: √ | AX3: √ | AZ3: √ | BB3: √ | BC3: 编辑 | BD3: √ | BE3: 编辑,导出 | BX3: √ | BY3: √ | BZ3: √ | CC3: √ | CS3: =COUNTIF(U3:CR3,"=√") -> 14
A4: 2 | B4: 基础资料 | C4: 客户资料 | D4: 法人客户档案 | E4: 全渠道 | F4: 法人 | G4: 是 | H4: CRM/AE/MBO | J4: 12036284 | L4: AMCS-基础资料-法人客户档案 | M4: AMCS-基础资料-交易公司 | O4: 3 | P4: 1、3 | U4: 见法人对账 | V4: √ | Z4: √ | AR4: √ | AW4: √ | AX4: √ | AZ4: √ | BB4: √ | BC4: 编辑 | BD4: √ | BE4: 导出 | BX4: √ | CS4: =COUNTIF(U4:CR4,"=√") -> 9
A5: 3 | B5: 基础资料 | C5: 客户资料 | D5: 供应商档案 | E5: 全渠道 | G5: 是 | H5: AE | J5: 12036282，12035823 | O5: 9 | S5: 除导出外不限 | AP5: √ | AQ5: √ | AR5: √ | AS5: 全部数据 | AT5: √ | AU5: √ | AW5: √ | AX5: √ | AY5: 编辑,全部数据 | BD5: √ | BE5: 导出,全部数据 | CS5: =COUNTIF(U5:CR5,"=√") -> 8
A6: 4 | B6: 基础资料 | C6: 客户资料 | D6: 分销商档案 | E6: 全渠道 | F6: 是 | G6: 是 | H6: AE | J6: 12036349 | O6: 3 | P6: 1、3 | S6: 除导出外不限 | T6: 编辑 | U6: √ | W6: √ | Z6: √ | AR6: √ | AS6: 编辑,失效,生效 | AW6: √ | AX6: √ | AY6: 编辑,失效,生效 | BD6: √ | BE6: 导出 | CC6: √ | CS6: =COUNTIF(U6:CR6,"=√") -> 8 | CT6: 46138.449 | CU6: 2026-4-26 10:47:01：莫小丽“新增运营及区域销售可操作失效与恢复生效按钮
A7: 231 | B7: 基础资料 | C7: 订单设置 | D7: 产品线关联设置 | E7: 全渠道 | G7: IT | H7: CRM/AE | J7: 12036136 | O7: 10 | P7: 未开发 | S7: 不限 | CS7: =COUNTIF(U7:CR7,"=√") -> 0
A8: 232 | B8: 基础资料 | C8: 订单设置 | D8: 产品渠道设置 | E8: 全渠道 | G8: IT | H8: CRM/AE | J8: 12036141 | O8: 10 | P8: 3 | S8: 不限 | CS8: =COUNTIF(U8:CR8,"=√") -> 0
A9: 233 | B9: 基础资料 | C9: 订单设置 | D9: 业务渠道设置 | E9: 全渠道 | G9: IT | H9: CRM/AE | J9: 12036145 | O9: 10 | P9: 3 | S9: 不限 | CS9: =COUNTIF(U9:CR9,"=√") -> 0
A10: 234 | B10: 基础资料 | C10: 订单设置 | D10: 产品线维护 | E10: 全渠道 | G10: IT | H10: CRM/AE | J10: 12036146 | O10: 10 | P10: 3 | S10: 不限 | CS10: =COUNTIF(U10:CR10,"=√") -> 0
A11: 235 | B11: 基础资料 | C11: 常规设置 | D11: 行政区域 | E11: 全渠道 | G11: IT | H11: CRM/AE/MBO | J11: 12036290，12036160 | O11: 10 | S11: 不限 | AM11: √ | AN11: √ | AP11: √ | AQ11: √ | AR11: √ | AS11: 全部数据 | AT11: √ | AU11: √ | AV11: √ | AW11: √ | AX11: √ | AY11: 全部数据 | BD11: √ | BE11: 全部数据 | CS11: =COUNTIF(U11:CR11,"=√") -> 11
A12: 236 | B12: 基础资料 | C12: 常规设置 | D12: 事业部设置 | E12: 全渠道 | G12: IT | H12: CRM/AE | J12: 12036287，12036150 | O12: 10 | P12: 无需配置 | S12: 不限 | CS12: =COUNTIF(U12:CR12,"=√") -> 0
A13: 237 | B13: 基础资料 | C13: 常规设置 | D13: 合同类型与销售渠道关联关系设置 | E13: 全渠道 | G13: IT | H13: AE | J13: 12036482 | O13: 10 | S13: 不限 | CS13: =COUNTIF(U13:CR13,"=√") -> 0
A14: 238 | B14: 基础资料 | C14: 常规设置 | D14: 项目进度定义 | E14: 工程 | G14: IT | H14: AE | J14: 12035897 | O14: 10 | S14: 不限 | CS14: =COUNTIF(U14:CR14,"=√") -> 0
A15: 5 | B15: 基础资料 | C15: 常规设置 | D15: 行政销售区域对照列表 | E15: 全渠道 | G15: 是 | H15: AE | J15: 12036463 | O15: 9 | S15: 不限 | AM15: √ | AP15: √ | AR15: √ | AS15: 编辑,导出 | BD15: √ | CS15: =COUNTIF(U15:CR15,"=√") -> 4
A16: 6 | B16: 基础资料 | C16: 常规设置 | D16: 单据审批人对照表 | E16: 全渠道 | H16: AE | J16: 12036464 | O16: 9 | S16: 不限 | AM16: √ | AP16: √ | AR16: √ | AS16: 编辑,导出 | BD16: √ | CS16: =COUNTIF(U16:CR16,"=√") -> 4
A17: 240 | B17: 基础资料 | C17: 常规设置 | D17: 数据权限设置 | E17: 全渠道 | G17: IT | H17: AE | J17: 12036163 | O17: 10 | S17: 不限 | CS17: =COUNTIF(U17:CR17,"=√") -> 0
A18: 241 | B18: 基础资料 | C18: 常规设置 | D18: 经销商配置 | E18: 全渠道 | G18: IT | H18: AE | J18: 12036389 | O18: 10 | S18: 不限 | CS18: =COUNTIF(U18:CR18,"=√") -> 0
A19: 289 | B19: 基础资料 | C19: 常规设置 | D19: AE和CRM事业部对应关系表配置 | E19: 全渠道 | G19: IT | H19: CRM/AE | O19: 10 | S19: 不限 | CS19: =COUNTIF(U19:CR19,"=√") -> 0
A20: 7 | B20: 基础资料 | C20: 常规设置 | D20: 节假日维护（无） | E20: 全渠道 | G20: 是 | H20: AE | J20: 12036492 | O20: 9 | S20: 不限 | AM20: √ | AR20: √ | AS20: 编辑,导出,全部数据 | BD20: √ | BE20: 全部数据 | CS20: =COUNTIF(U20:CR20,"=√") -> 3
A21: 8 | B21: 产品中心 | C21: 产品资料 | D21: 产品列表 | E21: 全渠道 | F21: 是 | G21: 是 | H21: CRM/AE | J21: 12036297 | O21: 3 | P21: 1、3 | T21: 导出 | U21: √ | W21: √ | X21: √ | Z21: √ | AC21: √ | AM21: √ | AN21: √ | AP21: √ | AQ21: √ | AR21: √ | AT21: √ | AU21: √ | AV21: √ | AW21: √ | AX21: √ | AY21: 关联事业部的全部 | AZ21: √ | BA21: √ | BB21: √ | BC21: 导出 | BD21: √ | BP21: √ | BQ21: √ | BR21: √ | BS21: √ | BU21: √ | BV21: √ | CS21: =COUNTIF(U21:CR21,"=√") -> 25 | CT21: 2026年4月22日21:15:52 | CU21: 区肇蓉+新增角色“产品查询（所有）、产品查询”+2026.4.22”
A22: 9 | B22: 产品中心 | C22: 产品资料 | D22: 产品变更列表 | E22: 全渠道 | G22: 是 | H22: CRM/AE | K22: 包含上下架、推广资料、图册与附件、关联产品 | O22: 9 | P22: 3 | BA22: √ | BB22: √ | BS22: √ | CS22: =COUNTIF(U22:CR22,"=√") -> 3
A23: 10 | B23: 产品中心 | C23: 产品资料 | D23: 产品推广等级字段要求配置 | E23: 全渠道 | G23: 是 | H23: CRM/AE | O23: 9 | P23: 3 | BT23: √ | CS23: =COUNTIF(U23:CR23,"=√") -> 1
A24: 11 | B24: 产品中心 | C24: 产品资料 | D24: 产品推广等级维护 | E24: 全渠道 | G24: 是 | H24: CRM/AE | O24: 9 | P24: 3 | BT24: √ | CJ24: 编辑,导出 | CS24: =COUNTIF(U24:CR24,"=√") -> 1
A25: 12 | B25: 产品中心 | C25: 产品资料 | D25: 产品图册维护（废弃原AE功能） | E25: 全渠道 | G25: 是 | H25: CRM/AE | J25: 12036299 | L25: AE产品图册上传 | M25: AE产品图册 | O25: 9 | BS25: √ | CS25: =COUNTIF(U25:CR25,"=√") -> 1
A26: 13 | B26: 产品中心 | C26: 产品资料 | D26: 产品SM状态变更申请 | E26: 全渠道 | G26: 是 | H26: AE | J26: 12036305 | O26: 4 | S26: 不限 | BU26: √ | BV26: √ | CS26: =COUNTIF(U26:CR26,"=√") -> 2
A27: 14 | B27: 产品中心 | C27: 说明书 | D27: 产品说明书 | E27: 全渠道 | G27: 是 | H27: AE | I27: 内 | J27: 12036368 | O27: 4 | P27: 3 | S27: 不限 | BW27: √ | CS27: =COUNTIF(U27:CR27,"=√") -> 1
A28: 15 | B28: 产品中心 | C28: 说明书 | D28: 说明书分类 | E28: 全渠道 | G28: 是 | H28: AE | J28: 12036367 | O28: 9 | S28: 除导出外不限 | BW28: √ | CS28: =COUNTIF(U28:CR28,"=√") -> 1
A29: 16 | B29: 产品中心 | C29: 说明书 | D29: 说明书查阅数据 | E29: 全渠道 | G29: 是 | H29: AE | J29: 12036369 | O29: 9 | P29: 无需配置 | S29: 除导出外不限 | BW29: √ | CS29: =COUNTIF(U29:CR29,"=√") -> 1
A30: 17 | B30: 产品中心 | C30: 说明书 | D30: 说明书关联产品 | E30: 全渠道 | G30: 是 | H30: AE | J30: 12036373 | O30: 9 | S30: 除导出外不限 | BW30: √ | CS30: =COUNTIF(U30:CR30,"=√") -> 1
A31: 242 | B31: 产品中心 | C31: 产品设置 | D31: (未来) | E31: 全渠道 | G31: IT | H31: CRM | L31: 经销商维护自选可售产品清单 | O31: 10 | CS31: =COUNTIF(U31:CR31,"=√") -> 0
A32: 18 | B32: 产品中心 | C32: 价目表 | D32: 价目表查询 | E32: 全渠道 | F32: 是 | G32: 是 | H32: CRM/AE | J32: 12036465 | K32: 12036466 | L32: 价目表 | O32: 3 | P32: 1、3 | U32: √ | W32: √ | X32: √ | Z32: √ | AI32: √ | AR32: √ | AT32: √ | AU32: √ | AV32: √ | AW32: √ | AX32: √ | AY32: 关联事业部的全部数据 | AZ32: √ | BA32: √ | BB32: √ | BD32: √ | BE32: 导出 | BN32: √ | BO32: √ | BZ32: √ | CS32: =COUNTIF(U32:CR32,"=√") -> 18 | CT32: 2026年4月25日10:55:52 | CU32: 区肇蓉+新增角色“价格查询、价格查询（导出）”+2026.4.25”
A33: 19 | B33: 产品中心 | C33: 库存 | D33: 库存查询 | E33: 全渠道 | F33: 是 | G33: 是 | H33: CRM/AE | J33: 12036152 | K33: 经销商/内部， | L33: 库存查询 | O33: 3 | P33: 1、3 | U33: √ | W33: √ | X33: √ | Y33: √ | Z33: √ | AJ33: √ | AL33: √ | AR33: √ | AT33: √ | AU33: √ | AV33: √ | AW33: √ | AX33: √ | AY33: 关联事业部的全部数据 | AZ33: √ | BA33: √ | BB33: √ | BD33: √ | BL33: √ | BM33: √ | CS33: =COUNTIF(U33:CR33,"=√") -> 19 | CT33: 2026年4月22日21:15:52 | CU33: 区肇蓉+新增角色“库存查询（映射）+2026.4.22”
A34: 20 | B34: 产品中心 | C34: 库存 | D34: 库存查询 | E34: 全渠道 | G34: 是，未来 | H34: CRM | K34: (内部-未来) | O34: 11 | AU34: √ | AV34: √ | AW34: √ | AX34: √ | AY34: 关联事业部的全部数据 | CS34: =COUNTIF(U34:CR34,"=√") -> 4
A35: 21 | B35: 产品中心 | C35: 库存 | D35: 事业部库存查询 | E35: 全渠道 | F35: 是 | G35: 是 | H35: CRM | K35: （经销商)责任制 | L35: 事业部库存查询 | P35: 1 | U35: √ | W35: √ | X35: √ | Y35: √ | Z35: √ | CS35: =COUNTIF(U35:CR35,"=√") -> 5 | CT35: 2026年4月18日17:32:52 | CU35: 区肇蓉，拿掉软装总监、软装经理关于“事业部库存查询”勾选，内部用户不涉及权限
A36: 22 | B36: 门店管理 | C36: 门店档案 | D36: 新建门店申请 | E36: 全渠道 | F36: 是 | G36: 是 | H36: AE | J36: 12036309 | O36: 3 | P36: 1、3 | S36: 除导出外不限 | T36: 编辑 | U36: √ | W36: √ | Z36: √ | AD36: √ | AR36: √ | AW36: √ | AX36: √ | AY36: 编辑 | BD36: √ | BE36: 导出 | CC36: √ | CS36: =COUNTIF(U36:CR36,"=√") -> 9
A37: 23 | B37: 门店管理 | C37: 门店档案 | D37: 门店档案 | E37: 全渠道 | F37: 是 | G37: 是 | H37: AE | J37: 12036311 | O37: 3 | P37: 1、3 | U37: √ | W37: √ | Z37: √ | AD37: √ | AR37: √ | AS37: 导出 | AW37: √ | AX37: √ | AY37: 导出 | BD37: √ | BE37: 导出 | BG37: √ | CC37: √ | CF37: √导出 | CS37: =COUNTIF(U37:CR37,"=√") -> 10
A38: 24 | B38: 门店管理 | C38: 门店档案 | D38: 门店变更申请 | E38: 全渠道 | F38: 是 | G38: 是 | H38: AE | J38: 12036312 | O38: 3 | P38: 1、3 | S38: 除导出外不限 | T38: 编辑 | U38: √ | W38: √ | Z38: √ | AD38: √ | AR38: √ | AW38: √ | AX38: √ | AY38: 编辑 | BD38: √ | BE38: 导出 | CC38: √ | CF38: √导出 | CS38: =COUNTIF(U38:CR38,"=√") -> 9
A39: 25 | B39: 门店管理 | C39: 门店设置 | D39: 门店照片设置 | E39: 全渠道 | H39: AE | J39: 12036313 | O39: 9 | P39: 3 | AR39: √ | AS39: 编辑,导出 | AW39: √ | AX39: √ | AY39: 关联事业部的全部数据 | BD39: √ | BE39: 导出 | CC39: √ | CS39: =COUNTIF(U39:CR39,"=√") -> 5
A40: 26 | B40: 门店管理 | C40: 门店设置 | D40: 门店验收信息设置 | E40: 全渠道 | H40: AE | J40: 12036421 | O40: 9 | AR40: √ | AS40: 编辑,导出 | AW40: √ | AX40: √ | AY40: 关联事业部的全部数据 | BD40: √ | BE40: 导出 | CS40: =COUNTIF(U40:CR40,"=√") -> 4
...

Sheet 新系统菜单样式
A1: 左侧平铺菜单样式（系统默认值）
A4: 左侧呼出菜单样式（用户可选1，仅影响个人账号样式）
A7: 顶部悬浮菜单样式（用户可选2，仅影响个人账号样式）
A10: 顶部及左侧固定菜单样式（用户可选3，仅影响个人账号样式）

Sheet 批量操作日志
A1: 更新时间 | B1: 更新内容
A2: 46138.446 | B2: 角色=大区管理“，可查看菜单调整为取“战略项目管理、工程项目管理、家装项目管理”菜单的合集

Sheet 权限下拉列表
B1: √ | G1: 按钮名称 | H1: 按钮类型
B2: 编辑 | G2: 详情页-编辑按钮 | H2: 编辑
B3: 查看流程 | G3: 详情页单据行-增加行按钮 | H3: 编辑
B4: 删除 | G4: 详情页单据行-增加子行按钮 | H4: 编辑
B5: 作废 | G5: 详情页单据行-删除行按钮 | H5: 删除
B6: 失效 | G6: 详情页-保存按钮 | H6: 保存
B7: 生效 | G7: 详情页-生效按钮 | H7: 生效
B8: 导入 | G8: 详情页-失效按钮 | H8: 失效
B9: 导出 | G9: 详情页-创建按钮 | H9: 编辑
B10: 申诉 | G10: 详情页单据行-删除按钮 | H10: 删除
B11: 更新标准地址及信息 | G11: 详情页-取消编辑按钮 | H11: 编辑
B12: 查重 | G12: 详情页-新建按钮 | H12: 编辑
... B31: 合同产品变更 | G31: 详情-打印按钮 | H31: 打印
B32: 生成订单
G33: 导出按钮 | H33: 导出
B34: 打印 | G34: 导入按钮 | H34: 导入
B35: 关联事业部的全部数据 | G35: 详情页单据行-新增按钮 | H35: 编辑
B36: 全部数据 | G36: 详情页-刷新按钮 | H36: 不限
B37: 个人创建的数据 | G37: 详情页单据行-引用政策产品 | H37: 编辑
B38: 个人管辖的经销商数据 | G38: 详情页-试算折扣率按钮 | H38: 编辑
B39: 项目经理为他 | G39: 列表页行-合同增补按钮 | H39: 增补合同
G40: 列表页行-失效按钮 | H40: 失效
G41: 列表页行-编辑按钮 | H41: 编辑
G42: 详情页-获取零售折扣底限按钮 | H42: 编辑
G43: 详情页-获取零售折扣按钮 | H43: 编辑
G44: 详情页-提交按钮 | H44: 编辑
G45: 合同增补 | H45: 增补合同
G46: 新建 | H46: 编辑
G47: 删除 | H47: 删除
G48: 查看 | H48: 不限
G49: 取消编辑按钮 | H49: 编辑
G50: 新建按钮 | H50: 编辑
G51: 删除按钮 | H51: 删除
... G71: 详情页-刷新数据按钮 | H71: 不限

Sheet 一级菜单
A1: 一级菜单 | B1: 二级序号 | C1: 菜单编码 | F1: 二级菜单 | G1: 二级序号 | H1: 三级菜单 | I1: 三级序号
A2: 基础资料 | B2: 1 | C2: =B2&A2 -> 1基础资料 | F2: 客户资料 | G2: 1 | H2: 经销商档案 | I2: 1
A3: 产品中心 | B3: 2 | C3: =B3&A3 -> 2产品中心 | F3: 订单设置 | G3: 2 | H3: 法人客户档案 | I3: 2
A4: 门店管理 | B4: 3 | C4: =B4&A4 -> 3门店管理 | F4: 常规设置 | G4: 3 | H4: 供应商档案 | I4: 3
A5: 工程管理 | B5: 4 | C5: =B5&A5 -> 4工程管理 | F5: 产品资料 | G5: 4 | H5: 分销商档案 | I5: 4
A6: 家装管理 | B6: 5 | C6: =B6&A6 -> 5家装管理 | F6: 说明书 | G6: 5 | H6: 产品线关联设置 | I6: 5
A7: 折扣政策 | B7: 6 | C7: =B7&A7 -> 6折扣政策 | F7: 产品设置 | G7: 6 | H7: 产品渠道设置 | I7: 6
A8: 采购订单 | B8: 7 | C8: =B8&A8 -> 7采购订单 | F8: 价目表 | G8: 7 | H8: 业务渠道设置 | I8: 7
A9: 经销商库存 | B9: 8 | C9: =B9&A9 -> 8经销商库存 | F9: 库存 | G9: 8 | H9: 产品线维护 | I9: 8
A10: 点将管理 | B10: 9 | C10: =B10&A10 -> 9点将管理 | F10: 门店档案 | G10: 9 | H10: 行政区域 | I10: 9
A11: 经销合同管理 | B11: 10 | C11: =B11&A11 -> 10经销合同管理 | F11: 门店设置 | G11: 10 | H11: 事业部设置 | I11: 10
A12: 电子合同管理 | B12: 11 | C12: =B12&A12 -> 11电子合同管理 | F12: 门店装修 | G12: 11 | H12: 合同类型与销售渠道关联关系设置 | I12: 11
A13: 财务管理 | B13: 12 | C13: =B13&A13 -> 12财务管理 | F13: 广告投放 | G13: 12 | H13: 项目进度定义 | I13: 12
... A20: 子账号管理 | B20: 19 | C20: =B20&A20 -> 19子账号管理 | F20: 服务费 | G20: 19 | H20: 产品信息变更申请 | I20: 19
F21: 真实性核销 | G21: 20 | H21: 产品推广等级字段要求配置 | I21: 20
F22: 报表中心 | G22: 21 | H22: 产品推广等级维护 | I22: 21
F23: 家装商机 | G23: 22 | H23: 产品图册维护 | I23: 22
F24: 家装合同 | G24: 23 | H24: 产品SM状态变更申请 | I24: 23
F25: 家装交付 | G25: 24 | H25: 产品说明书 | I25: 24
F26: 样品及长库龄折扣政策申请 | G26: 25 | H26: 说明书分类 | I26: 25
F27: 样品及长库龄折扣政策失效 | G27: 26 | H27: 说明书查阅数据 | I27: 26
F28: 折扣政策申请 | G28: 27 | H28: 说明书关联产品 | I28: 27
F29: 折扣政策失效 | G29: 28 | H29: 价目表查询 | I29: 28
F30: 折扣政策明细查询 | G30: 29 | H30: 库存查询 | I30: 29
F31: 订单查询 | G31: 30 | H31: 事业部库存查询 | I31: 30
F32: 出库单查询 | G32: 31 | H32: 新建门店申请 | I32: 31
... F56: 调整单 | G56: 55 | H56: 店面额度内兑现余额表 | I56: 55
G57: 56 | H57: 额度外台账 | I57: 56
F58: 问题反馈 | G58: 57 | H58: 额度内台账 | I58: 57
F59: 问题回复 | G59: 58 | H59: 兑现汇总 | I59: 58
F60: AE重复或合并的菜单 | G60: 59 | H60: 门店查询与分布 | I60: 59
G61: 60 | H61: 门店统计分析 | I61: 60
G62: 61 | H62: 门店区域分布 | I62: 61
G63: 62 | H63: 户外广告分布 | I63: 62
G64: 63 | H64: 门店分析 | I64: 63
G65: 64 | H65: 单体项目报备 | I65: 64
G66: 65 | H66: 项目进度更新 | I66: 65
G67: 66 | H67: 战略项目报备 | I67: 66
G68: 67 | H68: 工程项目档案 | I68: 67
G69: 68 | H69: 报备解冻申请 | I69: 68
...

Sheet Sheet8
A1: 一级菜单 | B1: 一级菜单序号 | C1: 二级菜单 | D1: 一级菜单编码 | E1: 一级菜单描述 | F1: 二级菜单序号 | G1: 二级菜单编码 | H1: 二级菜单 | K1: 内部可阅 | L1: 34
A2: 基础资料 | B2: =VLOOKUP(A2,'一级菜单'!A:C,3,0) -> 1基础资料 | C2: 客户资料 | D2: =B2&"_"&F2 -> 1基础资料_1 | E2: =A2&"/"&C2 -> 基础资料/客户资料 | F2: =VLOOKUP(C2,'一级菜单'!F:G,2,0) -> 1 | G2: =D2&"_"&I2 -> 1基础资料_1_1 | H2: 经销商档案 | I2: =VLOOKUP(H2,'一级菜单'!H:I,2,0) -> 1 | J2: =B2&"_"&F2&"_"&I2 -> 1基础资料_1_1 | K2: 是 | L2: CRM,AE,MBO
A3: 基础资料 | B3: =VLOOKUP(A3,'一级菜单'!A:C,3,0) -> 1基础资料 | C3: 客户资料 | D3: =B3&"_"&F3 -> 1基础资料_1 | E3: =A3&"/"&C3 -> 基础资料/客户资料 | F3: =VLOOKUP(C3,'一级菜单'!F:G,2,0) -> 1 | G3: =D3&"_"&I3 -> 1基础资料_1_2 | H3: 法人客户档案 | I3: =VLOOKUP(H3,'一级菜单'!H:I,2,0) -> 2 | J3: =B3&"_"&F3&"_"&I3 -> 1基础资料_1_2 | K3: 是 | L3: CRM,AE,MBO
A4: 基础资料 | B4: =VLOOKUP(A4,'一级菜单'!A:C,3,0) -> 1基础资料 | C4: 客户资料 | D4: =B4&"_"&F4 -> 1基础资料_1 | E4: =A4&"/"&C4 -> 基础资料/客户资料 | F4: =VLOOKUP(C4,'一级菜单'!F:G,2,0) -> 1 | G4: =D4&"_"&I4 -> 1基础资料_1_3 | H4: 供应商档案 | I4: =VLOOKUP(H4,'一级菜单'!H:I,2,0) -> 3 | J4: =B4&"_"&F4&"_"&I4 -> 1基础资料_1_3 | K4: 是 | L4: AE
A5: 基础资料 | B5: =VLOOKUP(A5,'一级菜单'!A:C,3,0) -> 1基础资料 | C5: 客户资料 | D5: =B5&"_"&F5 -> 1基础资料_1 | E5: =A5&"/"&C5 -> 基础资料/客户资料 | F5: =VLOOKUP(C5,'一级菜单'!F:G,2,0) -> 1 | G5: =D5&"_"&I5 -> 1基础资料_1_4 | H5: 分销商档案 | I5: =VLOOKUP(H5,'一级菜单'!H:I,2,0) -> 4 | J5: =B5&"_"&F5&"_"&I5 -> 1基础资料_1_4 | K5: 是 | L5: AE
A6: 基础资料 | B6: =VLOOKUP(A6,'一级菜单'!A:C,3,0) -> 1基础资料 | C6: 订单设置 | D6: =B6&"_"&F6 -> 1基础资料_2 | E6: =A6&"/"&C6 -> 基础资料/订单设置 | F6: =VLOOKUP(C6,'一级菜单'!F:G,2,0) -> 2 | G6: =D6&"_"&I6 -> 1基础资料_2_5 | H6: 产品线关联设置 | I6: =VLOOKUP(H6,'一级菜单'!H:I,2,0) -> 5 | J6: =B6&"_"&F6&"_"&I6 -> 1基础资料_2_5 | K6: IT | L6: CRM,AE
A7: 基础资料 | B7: =VLOOKUP(A7,'一级菜单'!A:C,3,0) -> 1基础资料 | C7: 订单设置 | D7: =B7&"_"&F7 -> 1基础资料_2 | E7: =A7&"/"&C7 -> 基础资料/订单设置 | F7: =VLOOKUP(C7,'一级菜单'!F:G,2,0) -> 2 | G7: =D7&"_"&I7 -> 1基础资料_2_6 | H7: 产品渠道设置 | I7: =VLOOKUP(H7,'一级菜单'!H:I,2,0) -> 6 | J7: =B7&"_"&F7&"_"&I7 -> 1基础资料_2_6 | K7: IT | L7: CRM,AE
A8: 基础资料 | B8: =VLOOKUP(A8,'一级菜单'!A:C,3,0) -> 1基础资料 | C8: 订单设置 | D8: =B8&"_"&F8 -> 1基础资料_2 | E8: =A8&"/"&C8 -> 基础资料/订单设置 | F8: =VLOOKUP(C8,'一级菜单'!F:G,2,0) -> 2 | G8: =D8&"_"&I8 -> 1基础资料_2_7 | H8: 业务渠道设置 | I8: =VLOOKUP(H8,'一级菜单'!H:I,2,0) -> 7 | J8: =B8&"_"&F8&"_"&I8 -> 1基础资料_2_7 | K8: IT | L8: CRM,AE
A9: 基础资料 | B9: =VLOOKUP(A9,'一级菜单'!A:C,3,0) -> 1基础资料 | C9: 订单设置 | D9: =B9&"_"&F9 -> 1基础资料_2 | E9: =A9&"/"&C9 -> 基础资料/订单设置 | F9: =VLOOKUP(C9,'一级菜单'!F:G,2,0) -> 2 | G9: =D9&"_"&I9 -> 1基础资料_2_8 | H9: 产品线维护 | I9: =VLOOKUP(H9,'一级菜单'!H:I,2,0) -> 8 | J9: =B9&"_"&F9&"_"&I9 -> 1基础资料_2_8 | K9: IT | L9: CRM,AE
A10: 基础资料 | B10: =VLOOKUP(A10,'一级菜单'!A:C,3,0) -> 1基础资料 | C10: 常规设置 | D10: =B10&"_"&F10 -> 1基础资料_3 | E10: =A10&"/"&C10 -> 基础资料/常规设置 | F10: =VLOOKUP(C10,'一级菜单'!F:G,2,0) -> 3 | G10: =D10&"_"&I10 -> 1基础资料_3_9 | H10: 行政区域 | I10: =VLOOKUP(H10,'一级菜单'!H:I,2,0) -> 9 | J10: =B10&"_"&F10&"_"&I10 -> 1基础资料_3_9 | K10: IT | L10: CRM,AE,MBO
A11: 基础资料 | B11: =VLOOKUP(A11,'一级菜单'!A:C,3,0) -> 1基础资料 | C11: 常规设置 | D11: =B11&"_"&F11 -> 1基础资料_3 | E11: =A11&"/"&C11 -> 基础资料/常规设置 | F11: =VLOOKUP(C11,'一级菜单'!F:G,2,0) -> 3 | G11: =D11&"_"&I11 -> 1基础资料_3_10 | H11: 事业部设置 | I11: =VLOOKUP(H11,'一级菜单'!H:I,2,0) -> 10 | J11: =B11&"_"&F11&"_"&I11 -> 1基础资料_3_10 | K11: IT | L11: CRM,AE
A12: 基础资料 | B12: =VLOOKUP(A12,'一级菜单'!A:C,3,0) -> 1基础资料 | C12: 常规设置 | D12: =B12&"_"&F12 -> 1基础资料_3 | E12: =A12&"/"&C12 -> 基础资料/常规设置 | F12: =VLOOKUP(C12,'一级菜单'!F:G,2,0) -> 3 | G12: =D12&"_"&I12 -> 1基础资料_3_11 | H12: 合同类型与销售渠道关联关系设置 | I12: =VLOOKUP(H12,'一级菜单'!H:I,2,0) -> 11 | J12: =B12&"_"&F12&"_"&I12 -> 1基础资料_3_11 | K12: IT | L12: AE
A13: 基础资料 | B13: =VLOOKUP(A13,'一级菜单'!A:C,3,0) -> 1基础资料 | C13: 常规设置 | D13: =B13&"_"&F13 -> 1基础资料_3 | E13: =A13&"/"&C13 -> 基础资料/常规设置 | F13: =VLOOKUP(C13,'一级菜单'!F:G,2,0) -> 3 | G13: =D13&"_"&I13 -> 1基础资料_3_12 | H13: 项目进度定义 | I13: =VLOOKUP(H13,'一级菜单'!H:I,2,0) -> 12 | J13: =B13&"_"&F13&"_"&I13 -> 1基础资料_3_12 | K13: IT | L13: AE
A14: 基础资料 | B14: =VLOOKUP(A14,'一级菜单'!A:C,3,0) -> 1基础资料 | C14: 常规设置 | D14: =B14&"_"&F14 -> 1基础资料_3 | E14: =A14&"/"&C14 -> 基础资料/常规设置 | F14: =VLOOKUP(C14,'一级菜单'!F:G,2,0) -> 3 | G14: =D14&"_"&I14 -> 1基础资料_3_13 | H14: 行政销售区域对照列表 | I14: =VLOOKUP(H14,'一级菜单'!H:I,2,0) -> 13 | J14: =B14&"_"&F14&"_"&I14 -> 1基础资料_3_13 | K14: 是 | L14: AE
A15: 基础资料 | B15: =VLOOKUP(A15,'一级菜单'!A:C,3,0) -> 1基础资料 | C15: 常规设置 | D15: =B15&"_"&F15 -> 1基础资料_3 | E15: =A15&"/"&C15 -> 基础资料/常规设置 | F15: =VLOOKUP(C15,'一级菜单'!F:G,2,0) -> 3 | G15: =D15&"_"&I15 -> 1基础资料_3_14 | H15: 单据审批人对照列表 | I15: =VLOOKUP(H15,'一级菜单'!H:I,2,0) -> 14 | J15: =B15&"_"&F15&"_"&I15 -> 1基础资料_3_14 | L15: AE
A16: 基础资料 | B16: =VLOOKUP(A16,'一级菜单'!A:C,3,0) -> 1基础资料 | C16: 常规设置 | D16: =B16&"_"&F16 -> 1基础资料_3 | E16: =A16&"/"&C16 -> 基础资料/常规设置 | F16: =VLOOKUP(C16,'一级菜单'!F:G,2,0) -> 3 | G16: =D16&"_"&I16 -> 1基础资料_3_10 | H16: 事业部设置 | I16: =VLOOKUP(H16,'一级菜单'!H:I,2,0) -> 10 | J16: =B16&"_"&F16&"_"&I16 -> 1基础资料_3_10 | K16: IT | L16: AE
A17: 基础资料 | B17: =VLOOKUP(A17,'一级菜单'!A:C,3,0) -> 1基础资料 | C17: 常规设置 | D17: =B17&"_"&F17 -> 1基础资料_3 | E17: =A17&"/"&C17 -> 基础资料/常规设置 | F17: =VLOOKUP(C17,'一级菜单'!F:G,2,0) -> 3 | G17: =D17&"_"&I17 -> 1基础资料_3_15 | H17: 数据权限设置 | I17: =VLOOKUP(H17,'一级菜单'!H:I,2,0) -> 15 | J17: =B17&"_"&F17&"_"&I17 -> 1基础资料_3_15 | K17: IT | L17: AE
A18: 基础资料 | B18: =VLOOKUP(A18,'一级菜单'!A:C,3,0) -> 1基础资料 | C18: 常规设置 | D18: =B18&"_"&F18 -> 1基础资料_3 | E18: =A18&"/"&C18 -> 基础资料/常规设置 | F18: =VLOOKUP(C18,'一级菜单'!F:G,2,0) -> 3 | G18: =D18&"_"&I18 -> 1基础资料_3_16 | H18: 经销商配置 | I18: =VLOOKUP(H18,'一级菜单'!H:I,2,0) -> 16 | J18: =B18&"_"&F18&"_"&I18 -> 1基础资料_3_16 | K18: IT | L18: AE
A19: 基础资料 | B19: =VLOOKUP(A19,'一级菜单'!A:C,3,0) -> 1基础资料 | C19: 常规设置 | D19: =B19&"_"&F19 -> 1基础资料_3 | E19: =A19&"/"&C19 -> 基础资料/常规设置 | F19: =VLOOKUP(C19,'一级菜单'!F:G,2,0) -> 3 | G19: =D19&"_"&I19 -> 1基础资料_3_17 | H19: 节假日维护 | I19: =VLOOKUP(H19,'一级菜单'!H:I,2,0) -> 17 | J19: =B19&"_"&F19&"_"&I19 -> 1基础资料_3_17 | K19: 是 | L19: AE
A20: 产品中心 | B20: =VLOOKUP(A20,'一级菜单'!A:C,3,0) -> 2产品中心 | C20: 产品资料 | D20: =B20&"_"&F20 -> 2产品中心_4 | E20: =A20&"/"&C20 -> 产品中心/产品资料 | F20: =VLOOKUP(C20,'一级菜单'!F:G,2,0) -> 4 | G20: =D20&"_"&I20 -> 2产品中心_4_18 | H20: 产品资料 | I20: =VLOOKUP(H20,'一级菜单'!H:I,2,0) -> 18 | J20: =B20&"_"&F20&"_"&I20 -> 2产品中心_4_18 | K20: 是 | L20: CRM,AE
A21: 产品中心 | B21: =VLOOKUP(A21,'一级菜单'!A:C,3,0) -> 2产品中心 | C21: 产品资料 | D21: =B21&"_"&F21 -> 2产品中心_4 | E21: =A21&"/"&C21 -> 产品中心/产品资料 | F21: =VLOOKUP(C21,'一级菜单'!F:G,2,0) -> 4 | G21: =D21&"_"&I21 -> 2产品中心_4_19 | H21: 产品信息变更申请 | I21: =VLOOKUP(H21,'一级菜单'!H:I,2,0) -> 19 | J21: =B21&"_"&F21&"_"&I21 -> 2产品中心_4_19 | K21: 是 | L21: CRM,AE
A22: 产品中心 | B22: =VLOOKUP(A22,'一级菜单'!A:C,3,0) -> 2产品中心 | C22: 产品资料 | D22: =B22&"_"&F22 -> 2产品中心_4 | E22: =A22&"/"&C22 -> 产品中心/产品资料 | F22: =VLOOKUP(C22,'一级菜单'!F:G,2,0) -> 4 | G22: =D22&"_"&I22 -> 2产品中心_4_20 | H22: 产品推广等级字段要求配置 | I22: =VLOOKUP(H22,'一级菜单'!H:I,2,0) -> 20 | J22: =B22&"_"&F22&"_"&I22 -> 2产品中心_4_20 | K22: 是 | L22: CRM,AE
A23: 产品中心 | B23: =VLOOKUP(A23,'一级菜单'!A:C,3,0) -> 2产品中心 | C23: 产品资料 | D23: =B23&"_"&F23 -> 2产品中心_4 | E23: =A23&"/"&C23 -> 产品中心/产品资料 | F23: =VLOOKUP(C23,'一级菜单'!F:G,2,0) -> 4 | G23: =D23&"_"&I23 -> 2产品中心_4_21 | H23: 产品推广等级维护 | I23: =VLOOKUP(H23,'一级菜单'!H:I,2,0) -> 21 | J23: =B23&"_"&F23&"_"&I23 -> 2产品中心_4_21 | K23: 是 | L23: CRM,AE
A24: 产品中心 | B24: =VLOOKUP(A24,'一级菜单'!A:C,3,0) -> 2产品中心 | C24: 产品资料 | D24: =B24&"_"&F24 -> 2产品中心_4 | E24: =A24&"/"&C24 -> 产品中心/产品资料 | F24: =VLOOKUP(C24,'一级菜单'!F:G,2,0) -> 4 | G24: =D24&"_"&I24 -> 2产品中心_4_22 | H24: 产品图册维护 | I24: =VLOOKUP(H24,'一级菜单'!H:I,2,0) -> 22 | J24: =B24&"_"&F24&"_"&I24 -> 2产品中心_4_22 | K24: 是 | L24: CRM,AE
A25: 产品中心 | B25: =VLOOKUP(A25,'一级菜单'!A:C,3,0) -> 2产品中心 | C25: 产品资料 | D25: =B25&"_"&F25 -> 2产品中心_4 | E25: =A25&"/"&C25 -> 产品中心/产品资料 | F25: =VLOOKUP(C25,'一级菜单'!F:G,2,0) -> 4 | G25: =D25&"_"&I25 -> 2产品中心_4_23 | H25: 产品SM状态变更申请 | I25: =VLOOKUP(H25,'一级菜单'!H:I,2,0) -> 23 | J25: =B25&"_"&F25&"_"&I25 -> 2产品中心_4_23 | K25: 是 | L25: AE
A26: 产品中心 | B26: =VLOOKUP(A26,'一级菜单'!A:C,3,0) -> 2产品中心 | C26: 说明书 | D26: =B26&"_"&F26 -> 2产品中心_5 | E26: =A26&"/"&C26 -> 产品中心/说明书 | F26: =VLOOKUP(C26,'一级菜单'!F:G,2,0) -> 5 | G26: =D26&"_"&I26 -> 2产品中心_5_24 | H26: 产品说明书 | I26: =VLOOKUP(H26,'一级菜单'!H:I,2,0) -> 24 | J26: =B26&"_"&F26&"_"&I26 -> 2产品中心_5_24 | K26: 是 | L26: AE
A27: 产品中心 | B27: =VLOOKUP(A27,'一级菜单'!A:C,3,0) -> 2产品中心 | C27: 说明书 | D27: =B27&"_"&F27 -> 2产品中心_5 | E27: =A27&"/"&C27 -> 产品中心/说明书 | F27: =VLOOKUP(C27,'一级菜单'!F:G,2,0) -> 5 | G27: =D27&"_"&I27 -> 2产品中心_5_25 | H27: 说明书分类 | I27: =VLOOKUP(H27,'一级菜单'!H:I,2,0) -> 25 | J27: =B27&"_"&F27&"_"&I27 -> 2产品中心_5_25 | K27: 是 | L27: AE
... A37: 门店管理 | B37: =VLOOKUP(A37,'一级菜单'!A:C,3,0) -> 3门店管理 | C37: 门店档案 | D37: =B37&"_"&F37 -> 3门店管理_9 | E37: =A37&"/"&C37 -> 门店管理/门店档案 | F37: =VLOOKUP(C37,'一级菜单'!F:G,2,0) -> 9 | G37: =D37&"_"&I37 -> 3门店管理_9_33 | H37: 门店变更申请 | I37: =VLOOKUP(H37,'一级菜单'!H:I,2,0) -> 33 | J37: =B37&"_"&F37&"_"&I37 -> 3门店管理_9_33 | K37: 是 | L37: AE
A38: 门店管理 | B38: =VLOOKUP(A38,'一级菜单'!A:C,3,0) -> 3门店管理 | C38: 门店设置 | D38: =B38&"_"&F38 -> 3门店管理_10 | E38: =A38&"/"&C38 -> 门店管理/门店设置 | F38: =VLOOKUP(C38,'一级菜单'!F:G,2,0) -> 10 | G38: =D38&"_"&I38 -> 3门店管理_10_34 | H38: 门店照片设置 | I38: =VLOOKUP(H38,'一级菜单'!H:I,2,0) -> 34 | J38: =B38&"_"&F38&"_"&I38 -> 3门店管理_10_34 | L38: AE
A39: 门店管理 | B39: =VLOOKUP(A39,'一级菜单'!A:C,3,0) -> 3门店管理 | C39: 门店设置 | D39: =B39&"_"&F39 -> 3门店管理_10 | E39: =A39&"/"&C39 -> 门店管理/门店设置 | F39: =VLOOKUP(C39,'一级菜单'!F:G,2,0) -> 10 | G39: =D39&"_"&I39 -> 3门店管理_10_35 | H39: 门店验收信息设置 | I39: =VLOOKUP(H39,'一级菜单'!H:I,2,0) -> 35 | J39: =B39&"_"&F39&"_"&I39 -> 3门店管理_10_35 | L39: AE
A40: 门店管理 | B40: =VLOOKUP(A40,'一级菜单'!A:C,3,0) -> 3门店管理 | C40: 门店设置 | D40: =B40&"_"&F40 -> 3门店管理_10 | E40: =A40&"/"&C40 -> 门店管理/门店设置 | F40: =VLOOKUP(C40,'一级菜单'!F:G,2,0) -> 10 | G40: =D40&"_"&I40 -> 3门店管理_10_36 | H40: 门店装修标准(新) | I40: =VLOOKUP(H40,'一级菜单'!H:I,2,0) -> 36 | J40: =B40&"_"&F40&"_"&I40 -> 3门店管理_10_36 | K40: 是 | L40: AE
A41: 门店管理 | B41: =VLOOKUP(A41,'一级菜单'!A:C,3,0) -> 3门店管理 | C41: 门店设置 | D41: =B41&"_"&F41 -> 3门店管理_10 | E41: =A41&"/"&C41 -> 门店管理/门店设置 | F41: =VLOOKUP(C41,'一级菜单'!F:G,2,0) -> 10 | G41: =D41&"_"&I41 -> 3门店管理_10_37 | H41: 门头展板报销标准-新 | I41: =VLOOKUP(H41,'一级菜单'!H:I,2,0) -> 37 | J41: =B41&"_"&F41&"_"&I41 -> 3门店管理_10_37 | K41: 是 | L41: AE
A42: 门店管理 | B42: =VLOOKUP(A42,'一级菜单'!A:C,3,0) -> 3门店管理 | C42: 门店设置 | D42: =B42&"_"&F42 -> 3门店管理_10 | E42: =A42&"/"&C42 -> 门店管理/门店设置 | F42: =VLOOKUP(C42,'一级菜单'!F:G,2,0) -> 10 | G42: =D42&"_"&I42 -> 3门店管理_10_38 | H42: 经销商额度外限额 | I42: =VLOOKUP(H42,'一级菜单'!H:I,2,0) -> 38 | J42: =B42&"_"&F42&"_"&I42 -> 3门店管理_10_38 | L42: AE
A43: 门店管理 | B43: =VLOOKUP(A43,'一级菜单'!A:C,3,0) -> 3门店管理 | C43: 门店装修 | D43: =B43&"_"&F43 -> 3门店管理_11 | E43: =A43&"/"&C43 -> 门店管理/门店装修 | F43: =VLOOKUP(C43,'一级菜单'!F:G,2,0) -> 11 | G43: =D43&"_"&I43 -> 3门店管理_11_39 | H43: 门店装修申请与进度更新 | I43: =VLOOKUP(H43,'一级菜单'!H:I,2,0) -> 39 | J43: =B43&"_"&F43&"_"&I43 -> 3门店管理_11_39 | K43: 是 | L43: AE
A44: 门店管理 | B44: =VLOOKUP(A44,'一级菜单'!A:C,3,0) -> 3门店管理 | C44: 门店装修 | D44: =B44&"_"&F44 -> 3门店管理_11 | E44: =A44&"/"&C44 -> 门店管理/门店装修 | F44: =VLOOKUP(C44,'一级菜单'!F:G,2,0) -> 11 | G44: =D44&"_"&I44 -> 3门店管理_11_40 | H44: 门店验收与报销单 | I44: =VLOOKUP(H44,'一级菜单'!H:I,2,0) -> 40 | J44: =B44&"_"&F44&"_"&I44 -> 3门店管理_11_40 | K44: 是 | L44: AE
A45: 门店管理 | B45: =VLOOKUP(A45,'一级菜单'!A:C,3,0) -> 3门店管理 | C45: 门店装修 | D45: =B45&"_"&F45 -> 3门店管理_11 | E45: =A45&"/"&C45 -> 门店管理/门店装修 | F45: =VLOOKUP(C45,'一级菜单'!F:G,2,0) -> 11 | G45: =D45&"_"&I45 -> 3门店管理_11_41 | H45: 门店装修额内兑现 | I45: =VLOOKUP(H45,'一级菜单'!H:I,2,0) -> 41 | J45: =B45&"_"&F45&"_"&I45 -> 3门店管理_11_41 | K45: 是 | L45: AE
A46: 门店管理 | B46: =VLOOKUP(A46,'一级菜单'!A:C,3,0) -> 3门店管理 | C46: 门店装修 | D46: =B46&"_"&F46 -> 3门店管理_11 | E46: =A46&"/"&C46 -> 门店管理/门店装修 | F46: =VLOOKUP(C46,'一级菜单'!F:G,2,0) -> 11 | G46: =D46&"_"&I46 -> 3门店管理_11_42 | H46: 额度内兑现批量复核 | I46: =VLOOKUP(H46,'一级菜单'!H:I,2,0) -> 42 | J46: =B46&"_"&F46&"_"&I46 -> 3门店管理_11_42 | K46: 财务 | L46: AE
A47: 门店管理 | B47: =VLOOKUP(A47,'一级菜单'!A:C,3,0) -> 3门店管理 | C47: 门店装修 | D47: =B47&"_"&F47 -> 3门店管理_11 | E47: =A47&"/"&C47 -> 门店管理/门店装修 | F47: =VLOOKUP(C47,'一级菜单'!F:G,2,0) -> 11 | G47: =D47&"_"&I47 -> 3门店管理_11_43 | H47: 门店装修额外兑现 | I47: =VLOOKUP(H47,'一级菜单'!H:I,2,0) -> 43 | J47: =B47&"_"&F47&"_"&I47 -> 3门店管理_11_43 | K47: 是 | L47: AE
A48: 门店管理 | B48: =VLOOKUP(A48,'一级菜单'!A:C,3,0) -> 3门店管理 | C48: 门店装修 | D48: =B48&"_"&F48 -> 3门店管理_11 | E48: =A48&"/"&C48 -> 门店管理/门店装修 | F48: =VLOOKUP(C48,'一级菜单'!F:G,2,0) -> 11 | G48: =D48&"_"&I48 -> 3门店管理_11_44 | H48: 门店装修申请变更 | I48: =VLOOKUP(H48,'一级菜单'!H:I,2,0) -> 44 | J48: =B48&"_"&F48&"_"&I48 -> 3门店管理_11_44 | K48: 是 | L48: AE
A49: 门店管理 | B49: =VLOOKUP(A49,'一级菜单'!A:C,3,0) -> 3门店管理 | C49: 门店装修 | D49: =B49&"_"&F49 -> 3门店管理_11 | E49: =A49&"/"&C49 -> 门店管理/门店装修 | F49: =VLOOKUP(C49,'一级菜单'!F:G,2,0) -> 11 | G49: =D49&"_"&I49 -> 3门店管理_11_45 | H49: 门店装修申请关闭 | I49: =VLOOKUP(H49,'一级菜单'!H:I,2,0) -> 45 | J49: =B49&"_"&F49&"_"&I49 -> 3门店管理_11_45 | K49: 是 | L49: AE
...

Sheet CRM计划菜单
A1: 序号 | B1: 进度 | C1: 适用对象 | D1: 一级菜单 | E1: 二级菜单 | G1: 预估人天 | H1: 备注
A2: 1 | B2: 开发中 | C2: CRM-经销商账号 | D2: 首页 | F2: =D2&E2 -> 首页
A3: 2 | B3: 开发中 | C3: CRM-经销商账号 | D3: 我的导入（异步） | F3: =D3&E3 -> 我的导入（异步）
A4: 3 | B4: 开发中 | C4: CRM-经销商账号 | D4: 我的导出（异步） | F4: =D4&E4 -> 我的导出（异步）
A5: 4 | B5: 开发中 | C5: CRM-经销商账号/内部用户 | D5: 经销商 | F5: =D5&E5 -> 经销商
A6: 5 | B6: 开发中 | C6: CRM-经销商账号 | D6: 产品 | F6: =D6&E6 -> 产品
A7: 6 | B7: 开发中 | C7: CRM-经销商账号 | D7: 销售订单 | E7: 订单查询 | F7: =D7&E7 -> 销售订单订单查询 | H7: 均在“销售订单”同一个界面展示
A8: 7 | B8: 开发中 | C8: CRM-经销商账号 | D8: 销售订单 | E8: 订单进度表查询 | F8: =D8&E8 -> 销售订单订单进度表查询 | H8: 均在“销售订单”同一个界面展示
A9: 8 | B9: 开发中 | C9: CRM-经销商账号 | D9: 销售订单 | E9: 创建常规订单 | F9: =D9&E9 -> 销售订单创建常规订单 | H9: 均在“销售订单”同一个界面展示
A10: 9 | B10: 开发中 | C10: CRM-经销商账号 | D10: 销售订单 | E10: 创建计划订单 | F10: =D10&E10 -> 销售订单创建计划订单 | H10: 均在“销售订单”同一个界面展示
A11: 10 | B11: 开发中 | C11: CRM-经销商账号 | D11: 销售订单 | E11: 创建广告物料订单 | F11: =D11&E11 -> 销售订单创建广告物料订单 | H11: 均在“销售订单”同一个界面展示
A12: 11 | B12: 开发中 | C12: CRM-经销商账号 | D12: 销售订单 | E12: 创建定制订单 | F12: =D12&E12 -> 销售订单创建定制订单 | H12: 均在“销售订单”同一个界面展示
A13: 12 | B13: 开发中 | C13: CRM-经销商账号 | D13: 销售订单 | E13: 创建转卖订单 | F13: =D13&E13 -> 销售订单创建转卖订单 | H13: 均在“销售订单”同一个界面展示
A14: 13 | B14: 开发中 | C14: CRM-经销商账号 | D14: 出口订单 | E14: 创建出口常规订单 | F14: =D14&E14 -> 出口订单创建出口常规订单 | H14: 出口客户才有的菜单，均在“出口订单”同一个界面展示
A15: 14 | B15: 开发中 | C15: CRM-经销商账号 | D15: 出口订单 | E15: 创建出口计划订单 | F15: =D15&E15 -> 出口订单创建出口计划订单 | H15: 出口客户才有的菜单，均在“出口订单”同一个界面展示
A16: 15 | B16: 开发中 | C16: CRM-经销商账号 | D16: 出口订单 | E16: 创建出口定制订单 | F16: =D16&E16 -> 出口订单创建出口定制订单 | H16: 出口客户才有的菜单，均在“出口订单”同一个界面展示
A17: 16 | B17: 开发中 | C17: CRM-经销商账号 | D17: 出口订单 | E17: 创建成品出口退货订单 | F17: =D17&E17 -> 出口订单创建成品出口退货订单 | H17: 出口客户才有的菜单，均在“出口订单”同一个界面展示
A18: 17 | B18: 开发中 | C18: CRM-经销商账号 | D18: 退货订单 | E18: 退货申请单查询 | F18: =D18&E18 -> 退货订单退货申请单查询 | H18: 均在“退货订单”同一个界面展示
... A20: 19 | B20: 开发中 | C20: CRM-经销商账号 | D20: 退货订单 | E20: 创建一件代发退货单 | F20: =D20&E20 -> 退货订单创建一件代发退货单 | H20: 均在“退货订单”同一个界面展示
A21: 20 | B21: 开发中 | C21: CRM-经销商账号 | D21: 经销商维护自选可售产品清单 | F21: =D21&E21 -> 经销商维护自选可售产品清单
A22: 21 | B22: 开发中 | C22: CRM-经销商账号 | D22: 出库单查询 | F22: =D22&E22 -> 出库单查询
A23: 22 | B23: 开发中 | C23: CRM-经销商账号 | D23: 库存查询 | F23: =D23&E23 -> 库存查询
A24: 23 | B24: 开发中 | C24: CRM-经销商账号 | D24: 事业部库存查询 | F24: =D24&E24 -> 事业部库存查询
A25: 24 | B25: 开发中 | C25: CRM-经销商账号 | D25: 折扣政策 | F25: =D25&E25 -> 折扣政策
A26: 25 | B26: 开发中 | C26: CRM-经销商账号 | D26: 对账单 | F26: =D26&E26 -> 对账单 | H26: 旧维度-经销商维度
A27: 26 | B27: 开发中 | C27: CRM-经销商账号 | D27: 发票信息 | F27: =D27&E27 -> 发票信息 | H27: 旧维度-经销商维度
A28: 27 | B28: 开发中 | C28: CRM-经销商账号 | D28: 数据管理 | E28: 退货申请单订单行导入 | F28: =D28&E28 -> 数据管理退货申请单订单行导入 | H28: 通用数据导入，均在“数据管理”同一个界面展示
A29: 28 | B29: 开发中 | C29: CRM-经销商账号 | D29: 数据管理 | E29: 2024销售订单头行导入 | F29: =D29&E29 -> 数据管理2024销售订单头行导入 | H29: 通用数据导入，均在“数据管理”同一个界面展示
A30: 29 | B30: 开发中 | C30: CRM-经销商账号 | D30: 数据管理 | E30: 2024销售订单行导入 | F30: =D30&E30 -> 数据管理2024销售订单行导入 | H30: 通用数据导入，均在“数据管理”同一个界面展示
A31: 30 | B31: 开发中 | C31: CRM-经销商账号 | D31: 收款认领 | F31: =D31&E31 -> 收款认领
A32: 31 | B32: 开发中 | C32: CRM-经销商账号 | D32: 审核未发运查询 | F32: =D32&E32 -> 审核未发运查询
A33: 32 | B33: 开发中 | C33: CRM-经销商账号 | D33: 月度库存上传 | F33: =D33&E33 -> 月度库存上传
A34: 33 | B34: 开发中 | C34: CRM-经销商账号 | D34: 经销商子账号管理 | F34: =D34&E34 -> 经销商子账号管理
A35: 34 | B35: 开发中 | C35: CRM-法人账号 | D35: 我的导出（异步） | F35: =D35&E35 -> 我的导出（异步）
A36: 35 | B36: 开发中 | C36: CRM-法人账号 | D36: 法人客户 | F36: =D36&E36 -> 法人客户
A37: 36 | B37: 开发中 | C37: CRM-法人账号 | D37: 法人对账单 | F37: =D37&E37 -> 法人对账单 | H37: 新版本
A38: 37 | B38: 开发中 | C38: CRM-法人账号 | D38: 对账单 | F38: =D38&E38 -> 对账单 | H38: 历史版本
A39: 38 | B39: 开发中 | C39: CRM-法人账号 | D39: 经销商账户明细查询 | F39: =D39&E39 -> 经销商账户明细查询
A40: 39 | B40: 开发中 | C40: CRM-法人账号 | D40: 待兑现折扣折让对账单 | F40: =D40&E40 -> 待兑现折扣折让对账单
A41: 40 | B41: 开发中 | C41: CRM-法人账号 | D41: 额度内市场推广费用对账单 | F41: =D41&E41 -> 额度内市场推广费用对账单
...

Sheet AE计划菜单
A1: 系统 | B1: 一级菜单 | C1: 二级菜单 | D1: 三级菜单 | G1: MENUNAME | H1: MENUID | I1: MENUNAME
A2: AMCS | B2: 营销中台 | C2: 基础资料 | D2: 基础资料 | G2: 合同产品变更 | H2: 12036157 | I2: 合同产品变更
A3: AMCS | B3: 营销中台 | C3: 基础资料 | D3: 经销商档案 | G3: 库存查询 | H3: 12036152 | I3: 库存查询
A4: AMCS | B4: 营销中台 | C4: 基础资料 | D4: 分销商档案 | G4: 客户资料 | H4: 12036115 | I4: 客户资料
A5: AMCS | B5: 营销中台 | C5: 基础资料 | D5: 法人客户档案 | G5: 自营工程合同 | H5: 12035907 | I5: 自营工程合同
A6: AMCS | B6: 营销中台 | C6: 基础资料 | D6: 交易公司 | G6: 自营工程签收 | H6: 12035854 | I6: 自营工程签收
A7: AMCS | B7: 营销中台 | C7: 基础资料 | D7: 供应商档案 | G7: 工程出库单 | H7: 12035853 | I7: 工程出库单
A8: AMCS | B8: 营销中台 | C8: 基础资料 | D8: 事业部设置 | G8: 工程要货订单 | H8: 12035851 | I8: 工程要货订单
A9: AMCS | B9: 营销中台 | C9: 基础资料 | D9: 行政区域 | G9: 工程折扣单 | H9: 12035849 | I9: 工程折扣单
A10: AMCS | B10: 营销中台 | C10: 基础资料 | D10: 合同类型与销售渠道关联关系设置 | G10: 项目合同变更 | H10: 12035845 | I10: 项目合同变更
A11: AMCS | B11: 营销中台 | C11: 门店管理 | D11: 广告费余额查询 | G11: 经销商工程合同 | H11: 12035844 | I11: 经销商工程合同
A12: AMCS | B12: 营销中台 | C12: 门店管理 | D12: 广告费余额调整 | G12: 项目进度更新 | H12: 12035834 | I12: 项目进度更新
A13: AMCS | B13: 营销中台 | C13: 门店管理 | D13: 广告费调整申请单 | G13: 折扣延期申请 | H13: 12036166 | I13: 折扣延期申请
... A180: EPMS | B180: 家装项目 | C180: 报表中心 | D180: 家装核销发票上传明细报表 | G180: 说明书分类 | H180: 12036367 | I180: 说明书分类
A181: 基础资料 | B181: 12035817 | C181: 不用的主菜单 | G181: 事业部设置 | H181: 12036150 | I181: 事业部设置
A182: 商机报备 | B182: 12035832 | C182: 不用的主菜单 | G182: 工程项目安装调试质量报表 | H182: 12036402 | I182: 工程项目安装调试质量报表
A183: 项目合同 | B183: 12035842 | C183: 不用的主菜单 | G183: 销售区域 | H183: 12035824 | I183: 销售区域
A184: 项目交付 | B184: 12035848 | C184: 不用的主菜单 | G184: 工程折扣政策申请 | H184: 12036490 | I184: 工程折扣政策申请
A185: 项目应付 | B185: 12035856 | C185: 不用的主菜单 | G185: 合同保证金标准设置 | H185: 12036500 | I185: 合同保证金标准设置
A186: 项目应收 | B186: 12035857 | C186: 不用的主菜单 | G186: 认缴概况 | H186: 12036499 | I186: 认缴概况
A187: 进度报表 | B187: 12035874 | C187: 不用的主菜单 | G187: 保证金减免申请 | H187: 12036498 | I187: 保证金减免申请
A188: 基础设置 | B188: 12036135 | C188: 不用的主菜单 | G188: 工程折扣政策失效 | H188: 12036491 | I188: 工程折扣政策失效
A189: 信息查询 | B189: 12036151 | C189: 不用的主菜单 | G189: 店面额度内兑现余额表 | H189: 12036488 | I189: 店面额度内兑现余额表
A190: 报表查询 | B190: 12036170 | C190: 不用的主菜单
A191: 紧急要货 | B191: 12036176 | C191: 不用的主菜单
A192: 家装交付 | B192: 12036218 | C192: 不用的主菜单
A193: 信息查询 | B193: 12036219 | C193: 不用的主菜单
A194: 报表查询 | B194: 12036220 | C194: 不用的主菜单
A195: 家装商机 | B195: 12036247 | C195: 不用的主菜单
A196: 家装合同 | B196: 12036260 | C196: 不用的主菜单
A197: 产品资料/图册 | B197: 12036266 | C197: 不用的主菜单
A198: 产品管理 | B198: 12036267 | C198: 不用的主菜单
A199: 销售合同 | B199: 12036275 | C199: 不用的主菜单
A200: 基础资料 | B200: 12036280 | C200: 不用的主菜单
A201: 门店档案 | B201: 12036301 | C201: 不用的主菜单
... A217: 真实性核销 | B217: 12036477 | C217: 不用的主菜单

Sheet 权限规则

Sheet 副本
N1: SIT权限检查（ 外部：1代表权限已配好，反之则为2。 内部：3代表、权限已配好，反之则为4） | T1: 查看当前账号关联的经销商（单个）数据 | AE1: 查看当前登录事业部的所有数据 | AN1: 以事业部维度，查看个人创建或个人关联经销商数据 | AR1: 以事业部维度，查看个人创建或个人关联经销商或当前部门下属所管辖经销商数据 | AT1: 查看当前登录事业部所有的数据 | BL1: MBO业务
A2: 菜单编码（唯一） | B2: 一级菜单 | C2: 二级菜单 | D2: 三级菜单 | E2: 经销商可阅 | F2: 内部可阅/废弃 | G2: 涉及系统 | H2: 需业务测试 | I2: AE_MENUID | J2: 备注 | K2: 原菜单路径1 | L2: 原菜单路径2 | M2: 原菜单路径3 | N2: 配置优先级 | O2: 技术配置 | P2: 汉得复核 | Q2: 箭牌复核sit | R2: 默认菜单按钮权限 | S2: █经销商权限█ | T2: 经销商 主账号 | U2: 法人账号 | V2: 经销商 负责人 | W2: 经销商 采购 | X2: 经销商 仓管 | Y2: 经销商 财务 | Z2: 经销商工程报备 | AA2: 经销商家装报备 | AB2: 经销商产品专员 | AC2: 出口经销商 | AD2: 电子合同签章 | AE2: 价格查询 | AF2: 工厂库存查询 | AG2: 工程报备专员 | AH2: 家装报备专员 | AI2: 报备查询 | AJ2: 工程合同专员 | AK2: 家装合同专员 | AL2: 运营管理 | AM2: █报备、合同、运营默认按钮权限█ | AN2: 战略工程项目管理 | AO2: 工程项目管理 | AP2: 家装项目管理 | AQ2: 区域销售代表 | AR2: 大区管理 | AS2: █项目、区域销售默认权限█ | AT2: 发货专员 | AU2: 调度专员 | AV2: 计划物流 | AW2: █发货、调度、物流默认权限█ | AX2: 销售财务 | AY2: █财务默认权限█ | AZ2: BI人员查看 | BA2: 自营工程签收 | BB2: 发票作废与取消核销 | BC2: 真实性核销审核 | BD2: 产品维护 | BE2: 产品推广等级维护 | BF2: 产品SM状态变更 | BG2: 售后产品SM状态变更 | BH2: 产品说明书维护 | BI2: 软装经理 | BJ2: 软装总监 | BK2: █产品维护权限█ | BL2: 培训师 | BM2: 活动策划师 | BN2: 设计师 | BO2: 培训管理员 | BP2: 活动策划管理员 | BQ2: 设计师管理员 | BR2: 集团合同管理员 | BS2: 问题反馈处理回复 | BT2: 菜单使用频率
A3: 1 | B3: 基础资料 | C3: 客户资料 | D3: 经销商档案 | E3: 是 | F3: 是 | G3: CRM/AE/MBO | H3: 是 | I3: 12036281，12036115 | J3: （查询+新建地址） | N3: 3 | O3: 待确认 | S3: 编辑 | T3: √ | V3: √ | Y3: √ | AL3: √ | AQ3: √ | AT3: √ | AV3: √ | AW3: 编辑 | AX3: √ | AY3: 编辑,导出 | BI3: √ | BJ3: √ | BT3: =COUNTIF(T3:BS3,"=√") -> 10
A4: 2 | B4: 基础资料 | C4: 客户资料 | D4: 法人客户档案 | E4: 法人 | F4: 是 | G4: CRM/AE/MBO | H4: 是 | I4: 12036284 | K4: AMCS-基础资料-法人客户档案 | L4: AMCS-基础资料-交易公司 | N4: 3 | T4: 见法人对账 | U4: √ | Y4: √ | AL4: √ | AQ4: √ | AT4: √ | AV4: √ | AW4: 编辑 | AX4: √ | AY4: 导出 | BI4: √ | BT4: =COUNTIF(T4:BS4,"=√") -> 8
A5: 3 | B5: 基础资料 | C5: 客户资料 | D5: 供应商档案 | F5: 是 | G5: AE | H5: 是 | I5: 12036282，12035823 | R5: 除导出外不限 | AJ5: √ | AK5: √ | AL5: √ | AM5: 全部数据 | AN5: √ | AO5: √ | AQ5: √ | AS5: 编辑,全部数据 | AX5: √ | AY5: 导出,全部数据 | BT5: =COUNTIF(T5:BS5,"=√") -> 7
A6: 4 | B6: 基础资料 | C6: 客户资料 | D6: 分销商档案 | E6: 是 | F6: 是 | G6: AE | H6: 是 | I6: 12036349 | N6: 3 | O6: 1、3 | R6: 除导出外不限 | S6: 编辑 | T6: √ | V6: √ | Y6: √ | AL6: √ | AQ6: √ | AS6: 编辑 | AX6: √ | AY6: 导出 | BT6: =COUNTIF(T6:BS6,"=√") -> 6
A7: 231 | B7: 基础资料 | C7: 订单设置 | D7: 产品线关联设置 | F7: IT | G7: CRM/AE | I7: 12036136 | R7: 不限 | BT7: =COUNTIF(T7:BS7,"=√") -> 0
A8: 232 | B8: 基础资料 | C8: 订单设置 | D8: 产品渠道设置 | F8: IT | G8: CRM/AE | I8: 12036141 | R8: 不限 | BT8: =COUNTIF(T8:BS8,"=√") -> 0
A9: 233 | B9: 基础资料 | C9: 订单设置 | D9: 业务渠道设置 | F9: IT | G9: CRM/AE | I9: 12036145 | R9: 不限 | BT9: =COUNTIF(T9:BS9,"=√") -> 0
A10: 234 | B10: 基础资料 | C10: 订单设置 | D10: 产品线维护 | F10: IT | G10: CRM/AE | I10: 12036146 | R10: 不限 | BT10: =COUNTIF(T10:BS10,"=√") -> 0
A11: 235 | B11: 基础资料 | C11: 常规设置 | D11: 行政区域 | F11: IT | G11: CRM/AE/MBO | I11: 12036290，12036160 | R11: 不限 | AG11: √ | AH11: √ | AJ11: √ | AK11: √ | AL11: √ | AM11: 全部数据 | AN11: √ | AO11: √ | AP11: √ | AQ11: √ | AS11: 全部数据 | AX11: √ | AY11: 全部数据 | BT11: =COUNTIF(T11:BS11,"=√") -> 10
A12: 236 | B12: 基础资料 | C12: 常规设置 | D12: 事业部设置 | F12: IT | G12: CRM/AE | I12: 12036287，12036150 | R12: 不限 | BT12: =COUNTIF(T12:BS12,"=√") -> 0
A13: 237 | B13: 基础资料 | C13: 常规设置 | D13: 合同类型与销售渠道关联关系设置 | F13: IT | G13: AE | I13: 12036482 | R13: 不限 | BT13: =COUNTIF(T13:BS13,"=√") -> 0
A14: 238 | B14: 基础资料 | C14: 常规设置 | D14: 项目进度定义 | F14: IT | G14: AE | I14: 12035897 | R14: 不限 | BT14: =COUNTIF(T14:BS14,"=√") -> 0
A15: 5 | B15: 基础资料 | C15: 常规设置 | D15: 行政销售区域对照列表 | F15: 是 | G15: AE | H15: 是 | I15: 12036463 | R15: 不限 | AG15: √ | AJ15: √ | AL15: √ | AM15: 编辑,导出 | AX15: √ | BT15: =COUNTIF(T15:BS15,"=√") -> 4
A16: 6 | B16: 基础资料 | C16: 常规设置 | D16: 单据审批人对照表 | G16: AE | H16: 是 | I16: 12036464 | R16: 不限 | AG16: √ | AJ16: √ | AL16: √ | AM16: 编辑,导出 | AX16: √ | BT16: =COUNTIF(T16:BS16,"=√") -> 4
A17: 240 | B17: 基础资料 | C17: 常规设置 | D17: 数据权限设置 | F17: IT | G17: AE | I17: 12036163 | R17: 不限 | BT17: =COUNTIF(T17:BS17,"=√") -> 0
A18: 241 | B18: 基础资料 | C18: 常规设置 | D18: 经销商配置 | F18: IT | G18: AE | I18: 12036389 | R18: 不限 | BT18: =COUNTIF(T18:BS18,"=√") -> 0
A19: 7 | B19: 基础资料 | C19: 常规设置 | D19: 节假日维护（无） | F19: 是 | G19: AE | H19: 是 | I19: 12036492 | R19: 不限 | AG19: √ | AL19: √ | AM19: 编辑,导出,全部数据 | AX19: √ | AY19: 全部数据 | BT19: =COUNTIF(T19:BS19,"=√") -> 3
A20: 8 | B20: 产品中心 | C20: 产品资料 | D20: 产品列表 | E20: 是 | F20: 是 | G20: CRM/AE | H20: 是 | I20: 12036297 | N20: 3 | S20: 导出 | T20: √ | V20: √ | W20: √ | Y20: √ | AB20: √ | AG20: √ | AH20: √ | AJ20: √ | AK20: √ | AL20: √ | AN20: √ | AO20: √ | AP20: √ | AQ20: √ | AR20: √ | AS20: 关联事业部的全部 | AT20: √ | AU20: √ | AV20: √ | AW20: 导出 | AX20: √ | BD20: √ | BF20: √ | BG20: √ | BT20: =COUNTIF(T20:BS20,"=√") -> 22
A21: 9 | B21: 产品中心 | C21: 产品资料 | D21: 产品变更列表 | F21: 是 | G21: CRM/AE | H21: 是 | J21: 包含上下架、推广资料、图册与附件、关联产品 | AU21: √ | AV21: √ | BD21: √ | BT21: =COUNTIF(T21:BS21,"=√") -> 3
A22: 10 | B22: 产品中心 | C22: 产品资料 | D22: 产品推广等级字段要求配置 | F22: 是 | G22: CRM/AE | H22: 是 | BE22: √ | BT22: =COUNTIF(T22:BS22,"=√") -> 1
A23: 11 | B23: 产品中心 | C23: 产品资料 | D23: 产品推广等级维护 | F23: 是 | G23: CRM/AE | H23: 是 | BE23: √ | BK23: 编辑,导出 | BT23: =COUNTIF(T23:BS23,"=√") -> 1
A24: 12 | B24: 产品中心 | C24: 产品资料 | D24: 产品图册维护（废弃原AE功能） | F24: 是 | G24: CRM/AE | H24: 是 | I24: 12036299 | K24: AE产品图册上传 | L24: AE产品图册 | BD24: √ | BT24: =COUNTIF(T24:BS24,"=√") -> 1
A25: 13 | B25: 产品中心 | C25: 产品资料 | D25: 产品SM状态变更申请 | F25: 是 | G25: AE | H25: 是 | I25: 12036305 | R25: 不限 | BF25: √ | BG25: √ | BT25: =COUNTIF(T25:BS25,"=√") -> 2
A26: 14 | B26: 产品中心 | C26: 说明书 | D26: 产品说明书 | F26: 是 | G26: AE | H26: 是 | I26: 12036368 | R26: 不限 | BH26: √ | BT26: =COUNTIF(T26:BS26,"=√") -> 1
A27: 15 | B27: 产品中心 | C27: 说明书 | D27: 说明书分类 | F27: 是 | G27: AE | H27: 是 | I27: 12036367 | R27: 除导出外不限 | BH27: √ | BT27: =COUNTIF(T27:BS27,"=√") -> 1
A28: 16 | B28: 产品中心 | C28: 说明书 | D28: 说明书查阅数据 | F28: 是 | G28: AE | I28: 12036369 | R28: 除导出外不限 | BH28: √ | BT28: =COUNTIF(T28:BS28,"=√") -> 1
A29: 17 | B29: 产品中心 | C29: 说明书 | D29: 说明书关联产品 | F29: 是 | G29: AE | I29: 12036373 | R29: 除导出外不限 | BH29: √ | BT29: =COUNTIF(T29:BS29,"=√") -> 1
A30: 242 | B30: 产品中心 | C30: 产品设置 | D30: (未来) | F30: IT | G30: CRM | K30: 经销商维护自选可售产品清单 | BT30: =COUNTIF(T30:BS30,"=√") -> 0
A31: 18 | B31: 产品中心 | C31: 价目表 | D31: 价目表查询 | E31: 是 | F31: 是 | G31: CRM/AE | H31: 是 | I31: 12036465 | J31: 12036466 | K31: 价目表 | N31: 3 | T31: √ | V31: √ | W31: √ | Y31: √ | AE31: √ | AL31: √ | AN31: √ | AO31: √ | AP31: √ | AQ31: √ | AR31: √ | AS31: 关联事业部的全部数据 | AT31: √ | AU31: √ | AV31: √ | AX31: √ | AY31: 导出 | BT31: =COUNTIF(T31:BS31,"=√") -> 15
A32: 19 | B32: 产品中心 | C32: 库存 | D32: 库存查询 | E32: 是 | F32: 是 | G32: CRM/AE | H32: 是 | I32: 12036152 | J32: 经销商/内部， | K32: 库存查询 | N32: 3 | T32: √ | V32: √ | W32: √ | X32: √ | Y32: √ | AF32: √ | AL32: √ | AN32: √ | AO32: √ | AP32: √ | AQ32: √ | AR32: √ | AS32: 关联事业部的全部数据 | AT32: √ | AU32: √ | AV32: √ | AX32: √ | BT32: =COUNTIF(T32:BS32,"=√") -> 16
A33: 20 | B33: 产品中心 | C33: 库存 | D33: 库存查询 | F33: 是，未来 | G33: CRM | J33: (内部-未来) | AO33: √ | AP33: √ | AQ33: √ | AS33: 关联事业部的全部数据 | BT33: =COUNTIF(T33:BS33,"=√") -> 3
A34: 21 | B34: 产品中心 | C34: 库存 | D34: 事业部库存查询 | E34: 是 | F34: 是 | G34: CRM | J34: （经销商)责任制 | K34: 事业部库存查询 | T34: √ | V34: √ | W34: √ | X34: √ | Y34: √ | BI34: √ | BJ34: √ | BT34: =COUNTIF(T34:BS34,"=√") -> 7
A35: 22 | B35: 门店管理 | C35: 门店档案 | D35: 新建门店申请 | E35: 是 | F35: 是 | G35: AE | H35: 是 | I35: 12036309 | N35: 3 | O35: 1、3 | R35: 除导出外不限 | S35: 编辑 | T35: √ | V35: √ | Y35: √ | AC35: √ | AL35: √ | AQ35: √ | AS35: 编辑 | AX35: √ | AY35: 导出 | BT35: =COUNTIF(T35:BS35,"=√") -> 7
A36: 23 | B36: 门店管理 | C36: 门店档案 | D36: 门店档案 | E36: 是 | F36: 是 | G36: AE | H36: 是 | I36: 12036311 | N36: 3 | O36: 1、3 | T36: √ | V36: √ | Y36: √ | AC36: √ | AL36: √ | AM36: 导出 | AQ36: √ | AS36: 导出 | AX36: √ | AY36: 导出 | AZ36: √ | BT36: =COUNTIF(T36:BS36,"=√") -> 8
A37: 24 | B37: 门店管理 | C37: 门店档案 | D37: 门店变更申请 | E37: 是 | F37: 是 | G37: AE | H37: 是 | I37: 12036312 | N37: 3 | O37: 1、3 | R37: 除导出外不限 | S37: 编辑 | T37: √ | V37: √ | Y37: √ | AC37: √ | AL37: √ | AQ37: √ | AS37: 编辑 | AX37: √ | AY37: 导出 | BT37: =COUNTIF(T37:BS37,"=√") -> 7
A38: 25 | B38: 门店管理 | C38: 门店设置 | D38: 门店照片设置 | G38: AE | I38: 12036313 | AL38: √ | AM38: 编辑,导出 | AQ38: √ | AS38: 关联事业部的全部数据 | AX38: √ | AY38: 导出 | BT38: =COUNTIF(T38:BS38,"=√") -> 3
A39: 26 | B39: 门店管理 | C39: 门店设置 | D39: 门店验收信息设置 | G39: AE | I39: 12036421 | AL39: √ | AM39: 编辑,导出 | AQ39: √ | AS39: 关联事业部的全部数据 | AX39: √ | AY39: 导出 | BT39: =COUNTIF(T39:BS39,"=√") -> 3
A40: 27 | B40: 门店管理 | C40: 门店设置 | D40: 门店装修标准 | F40: 是 | G40: AE | H40: 是 | I40: 12036422 | AL40: √ | AM40: 编辑,导出 | AQ40: √ | AS40: 关联事业部的全部数据 | AX40: √ | AY40: 导出 | BT40: =COUNTIF(T40:BS40,"=√") -> 3
...

Sheet MBO计划菜单
A1: 序号 | B1: 客户端 | C1: 模块 | D1: 一级菜单 | E1: 二级菜单 | F1: 三级菜单 | G1: 四级菜单 | H1: 合并 | I1: 备注 | J1: 业务确认
A2: 1 | B2: 经销商侧PC端 | C2: 到岸价 | D2: 采购管理 | E2: 经销商采购 | F2: 行程轨迹管理 | G2: 采购订单发运列表 | J2: 常规业务，正常使用
B3: 经销商侧PC端 | C3: 到岸价 | D3: 采购管理 | E3: 经销商采购 | F3: 行程轨迹管理 | G3: 出库单发运列表
A4: 2 | B4: 经销商侧PC端 | C4: 到岸价 | D4: 采购管理 | E4: 经销商采购 | F4: 异常反馈管理 | G4: 异常反馈列表
B5: 经销商侧PC端 | C5: 到岸价 | D5: 采购管理 | E5: 经销商采购 | F5: 异常反馈管理 | G5: 异常查询列表
A6: 3 | B6: 经销商侧PC端 | C6: 到岸价 | D6: 采购管理 | E6: 经销商采购 | F6: 待发运管理 | G6: 出库单确认列表
A7: 4 | B7: 经销商侧PC端 | C7: 到岸价 | D7: 采购管理 | E7: 经销商采购 | F7: 待确认收货 | G7: 待确认发货列表
A8: 5 | B8: 经销商侧PC端 | C8: 到岸价 | D8: 采购管理 | E8: 经销商采购 | F8: 异常费用 | G8: 异常费用
A9: 6 | B9: 品牌侧PC端 | C9: 到岸价 | D9: 采购管理 | E9: 经销商采购 | F9: 行程轨迹管理
A10: 7 | B10: 品牌侧PC端 | C10: 到岸价 | D10: 采购管理 | E10: 经销商采购 | F10: 异常反馈管理
A11: 8 | B11: 品牌侧PC端 | C11: 到岸价 | D11: 采购管理 | E11: 经销商采购 | F11: 确认发货配置项 | G11: 确认发货配置项列表
A12: 9 | B12: 品牌侧PC端 | C12: 电子合同 | D12: 经销商 | E12: 合同管理 | F12: 模板管理 | G12: 模版管理 | J12: 常规业务，正常使用
A13: 10 | B13: 品牌侧PC端 | C13: 电子合同 | D13: 经销商 | E13: 合同管理 | F13: 合同管理 | G13: 经销合同管理 | I13: 经销合同、装修协议、广告协议、授权书、联络函、点将合同
A14: 11 | B14: 品牌侧PC端 | C14: 电子合同 | D14: 经销商 | E14: 合同管理 | F14: 合同管理 | G14: 装修协议
A15: 12 | B15: 品牌侧PC端 | C15: 电子合同 | D15: 经销商 | E15: 合同管理 | F15: 合同管理 | G15: 广告协议
A16: 13 | B16: 品牌侧PC端 | C16: 电子合同 | D16: 经销商 | E16: 合同管理 | F16: 合同管理 | G16: 授权书管理 | I16: 导购营销助手APP，使用品牌侧账号登录 | J16: 反馈：已于25年初停用，不迁移 确认人：袁娱
B17: 品牌侧PC端 | C17: 电子合同 | D17: 经销商 | E17: 合同管理 | F17: 合同管理 | G17: 联络函管理
B18: 品牌侧PC端 | C18: 电子合同 | D18: 经销商 | E18: 合同管理 | F18: 合同管理 | G18: 点将合同(1.5)
B19: 品牌侧PC端 | C19: 电子合同 | D19: 经销商 | E19: 合同管理 | F19: 合同处理 | G19: 经销商拒签待处理
B20: 经销商侧PC端 | C20: 电子合同 | D20: 基础 | E20: 合同管理 | F20: 合同 | G20: 经销商合同
B21: 经销商侧PC端 | C21: 电子合同 | D21: 基础 | E21: 合同管理 | F21: 合同 | G21: 装修协议
B22: 经销商侧PC端 | C22: 电子合同 | D22: 基础 | E22: 合同管理 | F22: 合同 | G22: 广告协议
B23: 经销商侧PC端 | C23: 电子合同 | D23: 基础 | E23: 合同管理 | F23: 合同 | G23: 点将合同
B24: 经销商侧PC端 | C24: 电子合同 | D24: 基础 | E24: 合同管理 | F24: 合同 | G24: *所有合同
A25: 15 | B25: 品牌侧PC端 | C25: 分销订货会 | D25: 营销 | E25: 分销订货会 | F25: 分销商订货计划 | J25: 反馈：目前已没有使用，可以往后安排 确认人：林文宇
A26: 16 | B26: 品牌侧PC端 | C26: 分销订货会 | D26: 营销 | E26: 分销订货会 | F26: 分销商订货列表
A27: 17 | B27: 品牌侧PC端 | C27: 分销订货会 | D27: 营销 | E27: 分销订货会 | F27: 分销订货会审核
A28: 18 | B28: 品牌侧PC端 | C28: 分销订货会 | D28: 营销 | E28: 分销订货会 | F28: 分销订货会统计
A29: 19 | B29: 经销商侧PC端 | C29: 分销订货会 | D29: 营销 | E29: 分销订货会 | F29: 分销商订货计划
A30: 20 | B30: 经销商侧PC端 | C30: 分销订货会 | D30: 营销 | E30: 分销订货会 | F30: 分销商订货列表
A31: 21 | B31: 品牌侧PC端 | C31: 心声社区 | D31: 心声社区 | J31: 反馈：市场反馈由审计及营销管理部在使用（原对外入口由于数据安全问题已关闭），售后对接客服系统，均在正常使用 确认人：林文宇
A32: 22 | B32: 经销商侧PC端 | C32: 心声社区 | D32: 心声社区
A33: 28 | B33: 品牌侧PC端 | C33: 点将 | D33: 营销 | E33: 点将 | F33: 基础信息 | G33: 讲师档案 | J33: 常规业务，正常使用
B34: 品牌侧PC端 | C34: 点将 | D34: 营销 | E34: 点将 | F34: 基础信息 | G34: 讲师排期
B35: 品牌侧PC端 | C35: 点将 | D35: 营销 | E35: 点将 | F35: 基础信息 | G35: 策划师档案
B36: 品牌侧PC端 | C36: 点将 | D36: 营销 | E36: 点将 | F36: 基础信息 | G36: 培训师档案
B37: 品牌侧PC端 | C37: 点将 | D37: 营销 | E37: 点将 | F37: 基础信息 | G37: 设计师档案
B38: 品牌侧PC端 | C38: 点将 | D38: 营销 | E38: 点将 | F38: 基础信息 | G38: 策划师档案审批
B39: 品牌侧PC端 | C39: 点将 | D39: 营销 | E39: 点将 | F39: 基础信息 | G39: 培训师档案审批
B40: 品牌侧PC端 | C40: 点将 | D40: 营销 | E40: 点将 | F40: 基础信息 | G40: 设计师档案审批
...
